<?xml version="1.0" encoding="utf-8"?>
<!-- This URDF was automatically created by SolidWorks to URDF Exporter! Originally created by Stephen Brawner (brawner@gmail.com) 
     Commit Version: 1.6.0-4-g7f85cfe  Build Version: 1.6.7995.38578
     For more information, please see http://wiki.ros.org/sw_urdf_exporter -->
<robot
  name="mei">

  <mujoco>
    <compiler
    meshdir="../meshes"
    balanceinertia="true"
    discardvisual="false"/>
  </mujoco>


  <link
    name="base">
    <inertial>
      <origin
        xyz="0.00757956 -0.00020000 -0.00254703"
        rpy="0 0 0" />
      <mass
        value="4.87475244" />
      <inertia
        ixx="0.01839234"
        ixy="-0.00000757"
        ixz="0.00029559"
        iyy="0.05151497"
        iyz="-0.00000248"
        izz="0.06165645" />
    </inertial>
    <visual>
      <origin
        xyz="0 0 0"
        rpy="0 0 0" />
      <geometry>
        <mesh
          filename="../meshes/base.STL" />
      </geometry>
      <material
        name="">
        <color
          rgba="0.898039215686275 0.917647058823529 0.929411764705882 1" />
      </material>
    </visual>
    <collision>
      <origin
        xyz="0 0 0"
        rpy="0 0 0" />
      <geometry>
        <box size="0.272 0.214 0.116" />
      </geometry>
    </collision>
  </link>




  <link
    name="FL_hip">
    <inertial>
      <origin
        xyz="0.05950709 0.00087962 -0.00008074"
        rpy="0 0 0" />
      <mass
        value="0.64420378" />
      <inertia
        ixx="0.00043929"
        ixy="-0.00003659"
        ixz="0.00000254"
        iyy="0.00317400"
        iyz="-0.00000065"
        izz="0.00285293" />
    </inertial>
    <visual>
      <origin
        xyz="0 0 0"
        rpy="0 0 0" />
      <geometry>
        <mesh
          filename="../meshes/FL_hip.STL" />
      </geometry>
      <material
        name="">
        <color
          rgba="0.752941176470588 0.752941176470588 0.752941176470588 1" />
      </material>
    </visual>
    <collision>
      <origin rpy="1.5707963267948966 0 0" xyz="0.06676 0.08 0" />
      <geometry>
        <cylinder length="0.04" radius="0.046" />
      </geometry>
    </collision>

  </link>
  <joint
    name="FL_hip_joint"
    type="revolute">
    <origin
      xyz="0.1403 0.0497999999999999 0"
      rpy="0 0 0" />
    <parent
      link="base" />
    <child
      link="FL_hip" />
    <axis
      xyz="1 0 0" />
    <limit
      lower="-1.0036"
      upper="1.0036"
      effort="23.7"
      velocity="30" />
  </joint>

  <link
    name="FL_thigh">
    <inertial>
      <origin
        xyz="-0.00211808 0.04705244 -0.02176453"
        rpy="0 0 0" />
      <mass
        value="0.95855680" />
      <inertia
        ixx="0.00588428"
        ixy="0.00013952"
        ixz="-0.00022559"
        iyy="0.00387777"
        iyz="0.00144261"
        izz="0.00296068" />
    </inertial>
    <visual>
      <origin
        xyz="0 0 0"
        rpy="0 0 0" />
      <geometry>
        <mesh
          filename="../meshes/FL_thigh.STL" />
      </geometry>
      <material
        name="">
        <color
          rgba="0.698039215686274 0.698039215686274 0.698039215686274 1" />
      </material>
    </visual>
    <collision>
      <origin rpy="0 1.5707963267948966 0" xyz="-0.019 0.0691 -0.1" />
      <geometry>
        <box size="0.1 0.022 0.038" />
      </geometry>
    </collision>
  </link>
  <joint
    name="FL_thigh_joint"
    type="revolute">
    <origin
      xyz="0.0667562717871182 0.0201539382152824 0"
      rpy="0 0 0" />
    <parent
      link="FL_hip" />
    <child
      link="FL_thigh" />
    <axis
      xyz="0 1 0" />
    <limit
      lower="-0.56723"
      upper="4.9306"
      effort="23.7"
      velocity="30" />
  </joint>


  <link
    name="FL_calf">
    <inertial>
      <origin
        xyz=" 0.01455678 0.00000000 -0.12125055"
        rpy="0 0 0" />
      <mass
        value="0.14550479" />
      <inertia
        ixx="0.00316254"
        ixy="0.00000000"
        ixz="0.00030561"
        iyy="0.00321674"
        iyz="0.00000000"
        izz="0.00006635" />
    </inertial>
    <visual>
      <origin
        xyz="0 0 0"
        rpy="0 0 0" />
      <geometry>
        <mesh
          filename="../meshes/FL_calf.STL" />
      </geometry>
      <material
        name="">
        <color
          rgba="0.686274509803922 0.658823529411765 0.63921568627451 1" />
      </material>
    </visual>
    <collision>
      <origin rpy="0 -0.3 0" xyz="0.009 0 -0.028" />
      <geometry>
        <cylinder length="0.068" radius="0.01" />
      </geometry>
    </collision>
    <collision>
      <origin rpy="0 -0.27 0" xyz="0.029 0 -0.1" />
      <geometry>
        <cylinder length="0.038" radius="0.01" />
      </geometry>
    </collision>
    <collision>
      <origin rpy="0 0.11 0" xyz="0.031 0 -0.16" />
      <geometry>
        <cylinder length="0.04" radius="0.0125" />
      </geometry>
    </collision>

  </link>
  <joint
    name="FL_calf_joint"
    type="revolute">
    <origin
      xyz="0 0.0694 -0.220000111808529"
      rpy="0 0 0" />
    <parent
      link="FL_thigh" />
    <child
      link="FL_calf" />
    <axis
      xyz="0 1 0" />
    <limit
      lower="-2.618"
      upper="-0.69813"
      effort="35.55"
      velocity="30" />
  </joint>
  <link
    name="FL_foot">
    <inertial>
      <origin
        xyz="0 0 0"
        rpy="0 0 0" />
      <mass
        value="0.04" /> 
      <inertia
        ixx="9.6e-06"
        ixy="0"
        ixz="0"
        iyy="9.6e-06"
        iyz="0"
        izz="9.6e-06" />
    </inertial>
    <visual>
      <origin
        xyz="0 0 0"
        rpy="0 0 0" />
      <geometry>
        <mesh
          filename="../meshes/FL_foot.STL" />
      </geometry>
      <material
        name="">
        <color
          rgba="0.686274509803922 0.658823529411765 0.63921568627451 1" />
      </material>
    </visual>
    <collision>
      <origin rpy="0 0 0" xyz="0.016 0 0.015" />
      <geometry>
        <sphere  radius="0.02149" />
      </geometry>
    </collision>
  </link>
  <joint
    name="FL_foot_joint"
    type="fixed" dont_collapse="true">  
    <origin
      xyz="-0.0053877 0 -0.21902"
      rpy="0 0 0" />
    <parent
      link="FL_calf" />
    <child
      link="FL_foot" />
    <axis
      xyz="0 0 0" />
  </joint>



  <link
    name="FR_hip">
    <inertial>
      <origin
        xyz="0.05950709 0.00087962 0.00008074"
        rpy="0 0 0" />
      <mass
        value="0.64420378" />
      <inertia
        ixx="0.00043929"
        ixy="0.00003659"
        ixz="-0.00000254"
        iyy="0.00317400"
        iyz="-0.00000065"
        izz="0.00285293" />
    </inertial>
    <visual>
      <origin
        xyz="0 0 0"
        rpy="0 0 0" />
      <geometry>
        <mesh
          filename="../meshes/FR_hip.STL" />
      </geometry>
      <material
        name="">
        <color
          rgba="0.752941176470588 0.752941176470588 0.752941176470588 1" />
      </material>
    </visual>
    <collision>
      <origin rpy="1.5707963267948966 0 0" xyz="0.06676 -0.08 0" />
      <geometry>
        <cylinder length="0.04" radius="0.046" />
      </geometry>
    </collision>
  </link>
  <joint
    name="FR_hip_joint"
    type="revolute">
    <origin
      xyz="0.1403 -0.0502 0"
      rpy="0 0 0" />
    <parent
      link="base" />
    <child
      link="FR_hip" />
    <axis
      xyz="1 0 0" />
    <limit
      lower="-1.0036"
      upper="1.0036"
      effort="23.7"
      velocity="30" />
  </joint>
  <link
    name="FR_thigh">
    <inertial>
      <origin
        xyz="-0.00211808 -0.04705244 -0.02176453"
        rpy="0 0 0" />
      <mass
        value="0.95855680" />
      <inertia
        ixx="0.00588428"
        ixy="-0.00013952"
        ixz="-0.00022559"
        iyy="0.00387777"
        iyz="-0.00144261"
        izz="0.00296068" />
    </inertial>
    <visual>
      <origin
        xyz="0 0 0"
        rpy="0 0 0" />
      <geometry>
        <mesh
          filename="../meshes/FR_thigh.STL" />
      </geometry>
      <material
        name="">
        <color
          rgba="0.792156862745098 0.819607843137255 0.933333333333333 1" />
      </material>
    </visual>
    <collision>
      <origin rpy="0 1.5707963267948966 0" xyz="-0.019 -0.0691 -0.1" />
      <geometry>
        <box size="0.1 0.022 0.038" />
      </geometry>
    </collision>
  </link>
  <joint
    name="FR_thigh_joint"
    type="revolute">
    <origin
      xyz="0.0667562717871182 -0.0201539382152822 0"
      rpy="0 0 0" />
    <parent
      link="FR_hip" />
    <child
      link="FR_thigh" />
    <axis
      xyz="0 1 0" />
    <limit
      lower="-0.56723"
      upper="4.9306"
      effort="23.7"
      velocity="30" />
  </joint>
  <link
    name="FR_calf">
    <inertial>
      <origin
        xyz=" 0.01455678 0.00000000 -0.12125055"
        rpy="0 0 0" />
      <mass
        value="0.14550479" />
      <inertia
        ixx="0.00316254"
        ixy="0.00000000"
        ixz="0.00030561"
        iyy="0.00321674"
        iyz="0.00000000"
        izz="0.00006635" />
    </inertial>
    <visual>
      <origin
        xyz="0 0 0"
        rpy="0 0 0" />
      <geometry>
        <mesh
          filename="../meshes/FR_calf.STL" />
      </geometry>
      <material
        name="">
        <color
          rgba="0.792156862745098 0.819607843137255 0.933333333333333 1" />
      </material>
    </visual>
    <collision>
      <origin rpy="0 -0.3 0" xyz="0.009 0 -0.028" />
      <geometry>
        <cylinder length="0.068" radius="0.01" />
      </geometry>
    </collision>
    <collision>
      <origin rpy="0 -0.27 0" xyz="0.029 0 -0.1" />
      <geometry>
        <cylinder length="0.038" radius="0.01" />
      </geometry>
    </collision>
    <collision>
      <origin rpy="0 0.11 0" xyz="0.031 0 -0.16" />
      <geometry>
        <cylinder length="0.04" radius="0.0125" />
      </geometry>
    </collision>
  </link>
  <joint
    name="FR_calf_joint"
    type="revolute">
    <origin
      xyz="0 -0.0694 -0.220000111808525"
      rpy="0 0 0" />
    <parent
      link="FR_thigh" />
    <child
      link="FR_calf" />
    <axis
      xyz="0 1 0" />
    <limit
      lower="-2.618"
      upper="-0.69813"
      effort="35.55"
      velocity="20" />
  </joint>
  <link
    name="FR_foot">
    <inertial>
      <origin
        xyz="0 0 0"
        rpy="0 0 0" />
      <mass
        value="0.04" />
      <inertia
        ixx="9.6e-06"
        ixy="0"
        ixz="0"
        iyy="9.6e-06"
        iyz="0"
        izz="9.6e-06" />
    </inertial>
    <visual>
      <origin
        xyz="0 0 0"
        rpy="0 0 0" />
      <geometry>
        <mesh
          filename="../meshes/FR_foot.STL" />
      </geometry>
      <material
        name="">
        <color
          rgba="0.792156862745098 0.819607843137255 0.933333333333333 1" />
      </material>
    </visual>
    <collision>
      <origin rpy="0 0 0" xyz="0.016 0 0.015" />
      <geometry>
        <sphere  radius="0.02149" />
      </geometry>
    </collision>
  </link>
  <joint
    name="FR_foot_joint"
    type="fixed" dont_collapse="true">
    <origin
      xyz="-0.00538770972802349 0 -0.219020635804649"
      rpy="0 0 0" />
    <parent
      link="FR_calf" />
    <child
      link="FR_foot" />
    <axis
      xyz="0 0 0" />
  </joint>



  
  <link
    name="RL_hip">
    <inertial>
      <origin
        xyz="-0.05950709 0.00087962 0.00008074"
        rpy="0 0 0" />
      <mass
        value="0.64420378" />
      <inertia
        ixx="0.00043929"
        ixy="0.00003659"
        ixz="0.00000254"
        iyy="0.00317400"
        iyz="0.00000065"
        izz="0.00285293" />
    </inertial>
    <visual>
      <origin
        xyz="0 0 0"
        rpy="0 0 0" />
      <geometry>
        <mesh
          filename="../meshes/RL_hip.STL" />
      </geometry>
      <material
        name="">
        <color
          rgba="0.752941176470588 0.752941176470588 0.752941176470588 1" />
      </material>
    </visual>
    <collision>
      <origin rpy="1.5707963267948966 0 0" xyz="-0.06676 0.08 0" />
      <geometry>
        <cylinder length="0.04" radius="0.046" />
      </geometry>
    </collision>
  </link>
  <joint
    name="RL_hip_joint"
    type="revolute">
    <origin
      xyz="-0.1403 0.0498 0"
      rpy="0 0 0" />
    <parent
      link="base" />
    <child
      link="RL_hip" />
    <axis
      xyz="1 0 0" />
    <limit
      lower="-1.0036"
      upper="1.0036"
      effort="23.7"
      velocity="30" />
  </joint>
  <link
    name="RL_thigh">
    <inertial>
      <origin
        xyz="-0.00211808 0.04705244 -0.02176453"
        rpy="0 0 0" />
      <mass
        value="0.95855680" />
      <inertia
        ixx="0.00588428"
        ixy="0.00013952"
        ixz="-0.00022559"
        iyy="0.00387777"
        iyz="0.00144261"
        izz="0.00296068" />
    </inertial>
    <visual>
      <origin
        xyz="0 0 0"
        rpy="0 0 0" />
      <geometry>
        <mesh
          filename="../meshes/RL_thigh.STL" />
      </geometry>
      <material
        name="">
        <color
          rgba="0.698039215686274 0.698039215686274 0.698039215686274 1" />
      </material>
    </visual>
    <collision>
      <origin rpy="0 1.5707963267948966 0" xyz="-0.019 0.0691 -0.1" />
      <geometry>
        <box size="0.1 0.022 0.038" />
      </geometry>
    </collision>
  </link>
  <joint
    name="RL_thigh_joint"
    type="revolute">
    <origin
      xyz="-0.0667562717871183 0.0201539382152815 0"
      rpy="0 0 0" />
    <parent
      link="RL_hip" />
    <child
      link="RL_thigh" />
    <axis
      xyz="0 1 0" />
    <limit
      lower="-0.56723"
      upper="4.9306"
      effort="23.7"
      velocity="30" />
  </joint>
  <link
    name="RL_calf">
    <inertial>
      <origin
        xyz=" 0.01455678 0.00000000 -0.12125055"
        rpy="0 0 0" />
      <mass
        value="0.14550479" />
      <inertia
        ixx="0.00316254"
        ixy="0.00000000"
        ixz="0.00030561"
        iyy="0.00321674"
        iyz="0.00000000"
        izz="0.00006635" />
    </inertial>
    <visual>
      <origin
        xyz="0 0 0"
        rpy="0 0 0" />
      <geometry>
        <mesh
          filename="../meshes/RL_calf.STL" />
      </geometry>
      <material
        name="">
        <color
          rgba="0.898039215686275 0.917647058823529 0.929411764705882 1" />
      </material>
    </visual>
    <collision>
      <origin rpy="0 -0.3 0" xyz="0.009 0 -0.028" />
      <geometry>
        <cylinder length="0.068" radius="0.01" />
      </geometry>
    </collision>
    <collision>
      <origin rpy="0 -0.27 0" xyz="0.029 0 -0.1" />
      <geometry>
        <cylinder length="0.038" radius="0.01" />
      </geometry>
    </collision>
    <collision>
      <origin rpy="0 0.11 0" xyz="0.031 0 -0.16" />
      <geometry>
        <cylinder length="0.04" radius="0.0125" />
      </geometry>
    </collision>
  </link>
  <joint
    name="RL_calf_joint"
    type="revolute">
    <origin
      xyz="0 0.0694 -0.220000111808528"
      rpy="0 0 0" />
    <parent
      link="RL_thigh" />
    <child
      link="RL_calf" />
    <axis
      xyz="0 1 0" />
    <limit
      lower="-2.618"
      upper="-0.69813"
      effort="35.55"
      velocity="20" />
  </joint>
  <link
    name="RL_foot">
    <inertial>
      <origin
        xyz="0 0 0"
        rpy="0 0 0" />
      <mass
        value="0.04" />
      <inertia
        ixx="9.6e-06"
        ixy="0"
        ixz="0"
        iyy="9.6e-06"
        iyz="0"
        izz="9.6e-06" />
    </inertial>
    <visual>
      <origin
        xyz="0 0 0"
        rpy="0 0 0" />
      <geometry>
        <mesh
          filename="../meshes/RL_foot.STL" />
      </geometry>
      <material
        name="">
        <color
          rgba="0.686274509803922 0.658823529411765 0.63921568627451 1" />
      </material>
    </visual>
    <collision>
      <origin rpy="0 0 0" xyz="0.016 0 0.015" />
      <geometry>
        <sphere  radius="0.02149" />
      </geometry>
    </collision>
  </link>
  <joint
    name="RL_foot_joint"
    type="fixed" dont_collapse="true">
    <origin
      xyz="-0.00538770972802359 0 -0.219020635804649"
      rpy="0 0 0" />
    <parent
      link="RL_calf" />
    <child
      link="RL_foot" />
    <axis
      xyz="0 0 0" />
  </joint>




  <link
    name="RR_hip">
    <inertial>
      <origin
        xyz="-0.05950709 -0.00087962 -0.00008074"
        rpy="0 0 0" />
      <mass
        value="0.64420378" />
      <inertia
        ixx="0.00043929"
        ixy="-0.00003659"
        ixz="-0.00000254"
        iyy="0.00317400"
        iyz="0.00000065"
        izz="0.00285293" />
    </inertial>
    <visual>
      <origin
        xyz="0 0 0"
        rpy="0 0 0" />
      <geometry>
        <mesh
          filename="../meshes/RR_hip.STL" />
      </geometry>
      <material
        name="">
        <color
          rgba="1 1 1 1" />
      </material>
    </visual>
    <collision>
      <origin rpy="1.5707963267948966 0 0" xyz="-0.06676 -0.08 0" />
      <geometry>
        <cylinder length="0.04" radius="0.046" />
      </geometry>
    </collision>
  </link>
  <joint
    name="RR_hip_joint"
    type="revolute">
    <origin
      xyz="-0.1403 -0.0501999999999998 0"
      rpy="0 0 0" />
    <parent
      link="base" />
    <child
      link="RR_hip" />
    <axis
      xyz="1 0 0" />
    <limit
      lower="-1.0036"
      upper="1.0036"
      effort="23.7"
      velocity="30" />
  </joint>
  <link
    name="RR_thigh">
    <inertial>
      <origin
        xyz="-0.00211808 -0.04705244 -0.02176453"
        rpy="0 0 0" />
      <mass
        value="0.95855680" />
      <inertia
        ixx="0.00588428"
        ixy="-0.00013952"
        ixz="-0.00022559"
        iyy="0.00387777"
        iyz="-0.00144261"
        izz="0.00296068" />
    </inertial>
    <visual>
      <origin
        xyz="0 0 0"
        rpy="0 0 0" />
      <geometry>
        <mesh
          filename="../meshes/RR_thigh.STL" />
      </geometry>
      <material
        name="">
        <color
          rgba="0.792156862745098 0.819607843137255 0.933333333333333 1" />
      </material>
    </visual>
    <collision>
      <origin rpy="0 1.5707963267948966 0" xyz="-0.019 -0.0691 -0.1" />
      <geometry>
        <box size="0.1 0.022 0.038" />
      </geometry>
    </collision>
  </link>
  <joint
    name="RR_thigh_joint"
    type="revolute">
    <origin
      xyz="-0.0667562717871181 -0.0201539382152824 0"
      rpy="0 0 0" />
    <parent
      link="RR_hip" />
    <child
      link="RR_thigh" />
    <axis
      xyz="0 1 0" />
    <limit
      lower="-0.56723"
      upper="4.9306"
      effort="23.7"
      velocity="30" />
  </joint>
  <link
    name="RR_calf">
    <inertial>
      <origin
        xyz=" 0.01455678 0.00000000 -0.12125055"
        rpy="0 0 0" />
      <mass
        value="0.14550479" />
      <inertia
        ixx="0.00316254"
        ixy="0.00000000"
        ixz="0.00030561"
        iyy="0.00321674"
        iyz="0.00000000"
        izz="0.00006635" />
    </inertial>
    <visual>
      <origin
        xyz="0 0 0"
        rpy="0 0 0" />
      <geometry>
        <mesh
          filename="../meshes/RR_calf.STL" />
      </geometry>
      <material
        name="">
        <color
          rgba="0.792156862745098 0.819607843137255 0.933333333333333 1" />
      </material>
    </visual>
    <collision>
      <origin rpy="0 -0.3 0" xyz="0.009 0 -0.028" />
      <geometry>
        <cylinder length="0.068" radius="0.01" />
      </geometry>
    </collision>
    <collision>
      <origin rpy="0 -0.27 0" xyz="0.029 0 -0.1" />
      <geometry>
        <cylinder length="0.038" radius="0.01" />
      </geometry>
    </collision>
    <collision>
      <origin rpy="0 0.11 0" xyz="0.031 0 -0.16" />
      <geometry>
        <cylinder length="0.04" radius="0.0125" />
      </geometry>
    </collision>
  </link>
  <joint
    name="RR_calf_joint"
    type="revolute">
    <origin
      xyz="0 -0.0694 -0.22"
      rpy="0 0 0" />
    <parent
      link="RR_thigh" />
    <child
      link="RR_calf" />
    <axis
      xyz="0 1 0" />
    <limit
      lower="-2.618"
      upper="-0.69813"
      effort="35.55"
      velocity="20" />
  </joint>
  <link
    name="RR_foot">
    <inertial>
      <origin
        xyz="0 0 0"
        rpy="0 0 0" />
      <mass
        value="0.04" />
      <inertia
        ixx="9.6e-06"
        ixy="0"
        ixz="0"
        iyy="9.6e-06"
        iyz="0"
        izz="9.6e-06" />
    </inertial>
    <visual>
      <origin
        xyz="0 0 0"
        rpy="0 0 0" />
      <geometry>
        <mesh
          filename="../meshes/RR_foot.STL" />
      </geometry>
      <material
        name="">
        <color
          rgba="0.79216 0.81961 0.93333 1" />
      </material>
    </visual>
    <collision>
      <origin rpy="0 0 0" xyz="0.016 0 0.015" />
      <geometry>
        <sphere  radius="0.02149" />
      </geometry>
    </collision>
  </link>
  <joint
    name="RR_foot_joint"
    type="fixed" dont_collapse="true">
    <origin
      xyz="-0.0053877 0 -0.21902"
      rpy="0 0 0" />
    <parent
      link="RR_calf" />
    <child
      link="RR_foot" />
    <axis
      xyz="0 0 0" />
  </joint>
</robot>